<mujoco model="ant">
  <compiler angle="degree" coordinate="local" inertiafromgeom="true" />
  <option integrator="RK4" timestep="0.01" />
  <custom>
    <numeric data="0.0 0.0 0.55 1.0 0.0 0.0 0.0 0.0 1.0 0.0 -1.0 0.0 -1.0 0.0 1.0" name="init_qpos" />
  </custom>
  <default>
    <joint armature="1" damping="1" limited="true" />
    <geom conaffinity="0" condim="3" density="5.0" friction="1 0.5 0.5" margin="0.01"
      rgba="0.8 0.6 0.4 1" />
  </default>
  <asset>
    <texture builtin="gradient" height="100" rgb1="1 1 1" rgb2="0 0 0" type="skybox" width="100" />
    <texture builtin="flat" height="1278" mark="cross" markrgb="1 1 1" name="texgeom" random="0.01"
      rgb1="0.8 0.6 0.4" rgb2="0.8 0.6 0.4" type="cube" width="127" />
    <texture builtin="checker" height="100" name="texplane" rgb1="0 0 0" rgb2="0.8 0.8 0.8"
      type="2d" width="100" />
    <material name="MatPlane" reflectance="0.5" shininess="1" specular="1" texrepeat="60 60"
      texture="texplane" />
    <material name="geom" texture="texgeom" texuniform="true" />
  </asset>
  <worldbody>
    <light cutoff="100" diffuse="1 1 1" dir="-0 0 -1.3" directional="true" exponent="1"
      pos="0 0 1.3" specular=".1 .1 .1" />
    <geom conaffinity="1" condim="3" material="MatPlane" name="floor" pos="0 0 0"
      rgba="0.8 0.9 0.8 1" size="40 40 40" type="plane" />
    <body name="torso" pos="0 0 0.75">
      <camera name="track" mode="trackcom" pos="0 -3 0.3" xyaxes="1 0 0 0 0 1" />
      <geom fromto="-5 0 0 -4.5 0 0" name="torso_geom" size="0.09" type="capsule" />
      <joint armature="0" damping="0" limited="false" margin="0.01" name="root" pos="0 0 0"
        type="free" />
      <body name="front_left_leg" pos="-5 0 0">
        <geom fromto="0.0 0.0 0.0 -0.2 0.2 0.0" name="aux_1_geom" size="0.046" type="capsule" />
        <body name="aux_1" pos="-0.2 0.2 0">
          <joint axis="0 0 1" name="hip_1" pos="0.0 0.0 0.0" range="-30 30" type="hinge" />
          <geom fromto="0.0 0.0 0.0 -0.2 0.2 0.0" name="front_right_leg_geom" size="0.046"
            type="capsule" />
          <body pos="-0.2 0.2 0">
            <joint axis="1 1 0" name="ankle_1" pos="0.0 0.0 0.0" range="-70 -30" type="hinge" />
            <geom fromto="0.0 0.0 0.0 -0.4 0.4 0.0" name="first_right_ankle_geom" size="0.046"
              type="capsule" />
          </body>
        </body>
      </body>
      <body name="back_right_leg" pos="-5 0 0">
        <geom fromto="0.0 0.0 0.0 -0.2 -0.2 0.0" name="aux_2_geom" size="0.046" type="capsule" />
        <body name="aux_2" pos="-0.2 -0.2 0">
          <joint axis="0 0 1" name="hip_2" pos="0.0 0.0 0.0" range="-30 30" type="hinge" />
          <geom fromto="0.0 0.0 0.0 -0.2 -0.2 0.0" name="back_right_leg_geom" size="0.046"
            type="capsule" />
          <body pos="-0.2 -0.2 0">
            <joint axis="-1 1 0" name="ankle_2" pos="0.0 0.0 0.0" range="-70 -30" type="hinge" />
            <geom fromto="0.0 0.0 0.0 -0.4 -0.4 0.0" name="second_right_ankle_geom" size="0.046"
              type="capsule" />
          </body>
        </body>
      </body>
      <body name="front_1_leg" pos="-4.5 0 0">
        <geom fromto="0.0 0.0 0.0 0.0 -0.2828427 0.0" name="aux_3_geom" size="0.046" type="capsule" />
        <body name="aux_3" pos="0.0 -0.2828427 0">
          <joint axis="0 0 1" name="hip_3" pos="0.0 0.0 0.0" range="-30 30" type="hinge" />
          <geom fromto="0.0 0.0 0.0 0.0 -0.2828427 0.0" name="front_1_leg_geom" size="0.046"
            type="capsule" />
          <body pos="0.0 -0.2828427 0">
            <joint axis="1 1 0" name="ankle_3" pos="0.0 0.0 0.0" range="30 70" type="hinge" />
            <geom fromto="0.0 0.0 0.0 0.0 -0.56568542 0.0" name="front_3_ankle_geom" size="0.046"
              type="capsule" />
          </body>
        </body>
      </body>
      <body name="back_1_leg" pos="-4.5 0 0">
        <geom fromto="0.0 0.0 0.0 0.0 0.2828427 0.0" name="aux_4_geom" size="0.046" type="capsule" />
        <body name="aux_4" pos="0.0 0.2828427 0">
          <joint axis="0 0 1" name="hip_4" pos="0.0 0.0 0.0" range="-30 30" type="hinge" />
          <geom fromto="0.0 0.0 0.0 0.0 0.2828427 0.0" name="back_1_leg_geom" size="0.046"
            type="capsule" />
          <body pos="0.0 0.2828427 0">
            <joint axis="1 1 0" name="ankle_4" pos="0.0 0.0 0.0" range="-70 -30" type="hinge" />
            <geom fromto="0.0 0.0 0.0 0.0 0.56568542 0.0" name="back_3_ankle_geom" size="0.046"
              type="capsule" />
          </body>
        </body>
      </body>
      <body name="seg1" pos="-4.5 0 0">
        <joint axis="0 0 1" name="seg_1" pos="0.0 0.0 0.0" range="-30 30" type="hinge" />
        <geom fromto="0.0 0.0 0.0 0.5 0.0 0.0" name="seg_1_geom" size="0.09" type="capsule" />
        <body name="front_2_leg" pos=".5 0 0">
          <geom fromto="0.0 0.0 0.0 0.0 -0.2828427 0.0" name="aux_5_geom" size="0.046" type="capsule" />
          <body name="aux_5" pos="0.0 -0.2828427 0">
            <joint axis="0 0 1" name="hip_5" pos="0.0 0.0 0.0" range="-30 30" type="hinge" />
            <geom fromto="0.0 0.0 0.0 0.0 -0.2828427 0.0" name="front_5_leg_geom" size="0.046"
              type="capsule" />
            <body pos="0.0 -0.2828427 0">
              <joint axis="1 1 0" name="ankle_5" pos="0.0 0.0 0.0" range="30 70" type="hinge" />
              <geom fromto="0.0 0.0 0.0 0.0 -0.56568542 0.0" name="front_5_ankle_geom" size="0.046"
                type="capsule" />
            </body>
          </body>
        </body>
        <body name="back_2_leg" pos=".5 0 0">
          <geom fromto="0.0 0.0 0.0 0.0 0.2828427 0.0" name="aux_6_geom" size="0.046" type="capsule" />
          <body name="aux_6" pos="0.0 0.2828427 0">
            <joint axis="0 0 1" name="hip_6" pos="0.0 0.0 0.0" range="-30 30" type="hinge" />
            <geom fromto="0.0 0.0 0.0 0.0 0.2828427 0.0" name="back_2_leg_geom" size="0.046"
              type="capsule" />
            <body pos="0.0 0.2828427 0">
              <joint axis="1 1 0" name="ankle_6" pos="0.0 0.0 0.0" range="-70 -30" type="hinge" />
              <geom fromto="0.0 0.0 0.0 0.0 0.56568542 0.0" name="back_6_ankle_geom" size="0.046"
                type="capsule" />
            </body>
          </body>
        </body>
        <body name="seg2" pos=".5 0 0">
          <joint axis="0 0 1" name="seg_2" pos="0.0 0.0 0.0" range="-30 30" type="hinge" />
          <geom fromto="0.0 0.0 0.0 0.5 0.0 0.0" name="seg_2_geom" size="0.09" type="capsule" />
          <body name="front_3_leg" pos=".5 0 0">
            <geom fromto="0.0 0.0 0.0 0.0 -0.2828427 0.0" name="aux_7_geom" size="0.046"
              type="capsule" />
            <body name="aux_7" pos="0.0 -0.2828427 0">
              <joint axis="0 0 1" name="hip_7" pos="0.0 0.0 0.0" range="-30 30" type="hinge" />
              <geom fromto="0.0 0.0 0.0 0.0 -0.2828427 0.0" name="front_2_leg_geom" size="0.046"
                type="capsule" />
              <body pos="0.0 -0.2828427 0">
                <joint axis="1 1 0" name="ankle_7" pos="0.0 0.0 0.0" range="30 70" type="hinge" />
                <geom fromto="0.0 0.0 0.0 0.0 -0.56568542 0.0" name="front_7_ankle_geom" size="0.046"
                  type="capsule" />
              </body>
            </body>
          </body>
          <body name="back_3_leg" pos=".5 0 0">
            <geom fromto="0.0 0.0 0.0 0.0 0.2828427 0.0" name="aux_8_geom" size="0.046"
              type="capsule" />
            <body name="aux_8" pos="0.0 0.2828427 0">
              <joint axis="0 0 1" name="hip_8" pos="0.0 0.0 0.0" range="-30 30" type="hinge" />
              <geom fromto="0.0 0.0 0.0 0.0 0.2828427 0.0" name="back_3_leg_geom" size="0.046"
                type="capsule" />
              <body pos="0.0 0.2828427 0">
                <joint axis="1 1 0" name="ankle_8" pos="0.0 0.0 0.0" range="-70 -30" type="hinge" />
                <geom fromto="0.0 0.0 0.0 0.0 0.56568542 0.0" name="back_8_ankle_geom" size="0.046"
                  type="capsule" />
              </body>
            </body>
          </body>
          <body name="seg3" pos=".5 0 0">
            <joint axis="0 0 1" name="seg_3" pos="0.0 0.0 0.0" range="-30 30" type="hinge" />
            <geom fromto="0.0 0.0 0.0 0.5 0.0 0.0" name="seg_3_geom" size="0.09" type="capsule" />
            <body name="front_4_leg" pos=".5 0 0">
              <geom fromto="0.0 0.0 0.0 0.0 -0.2828427 0.0" name="aux_9_geom" size="0.046"
                type="capsule" />
              <body name="aux_9" pos="0.0 -0.2828427 0">
                <joint axis="0 0 1" name="hip_9" pos="0.0 0.0 0.0" range="-30 30" type="hinge" />
                <geom fromto="0.0 0.0 0.0 0.0 -0.2828427 0.0" name="front_3_leg_geom" size="0.046"
                  type="capsule" />
                <body pos="0.0 -0.2828427 0">
                  <joint axis="1 1 0" name="ankle_9" pos="0.0 0.0 0.0" range="30 70" type="hinge" />
                  <geom fromto="0.0 0.0 0.0 0.0 -0.56568542 0.0" name="front_9_ankle_geom"
                    size="0.046"
                    type="capsule" />
                </body>
              </body>
            </body>
            <body name="back_4_leg" pos=".5 0 0">
              <geom fromto="0.0 0.0 0.0 0.0 0.2828427 0.0" name="aux_10_geom" size="0.046"
                type="capsule" />
              <body name="aux_10" pos="0.0 0.2828427 0">
                <joint axis="0 0 1" name="hip_10" pos="0.0 0.0 0.0" range="-30 30" type="hinge" />
                <geom fromto="0.0 0.0 0.0 0.0 0.2828427 0.0" name="back_4_leg_geom" size="0.046"
                  type="capsule" />
                <body pos="0.0 0.2828427 0">
                  <joint axis="1 1 0" name="ankle_10" pos="0.0 0.0 0.0" range="-70 -30" type="hinge" />
                  <geom fromto="0.0 0.0 0.0 0.0 0.56568542 0.0" name="back_10_ankle_geom"
                    size="0.046"
                    type="capsule" />
                </body>
              </body>
            </body>
            <body name="seg4" pos=".5 0 0">
              <joint axis="0 0 1" name="seg_4" pos="0.0 0.0 0.0" range="-30 30" type="hinge" />
              <geom fromto="0.0 0.0 0.0 0.5 0.0 0.0" name="seg_4_geom" size="0.09" type="capsule" />
              <body name="front_5_leg" pos=".5 0 0">
                <geom fromto="0.0 0.0 0.0 0.0 -0.2828427 0.0" name="aux_11_geom" size="0.046"
                  type="capsule" />
                <body name="aux_11" pos="0.0 -0.2828427 0">
                  <joint axis="0 0 1" name="hip_11" pos="0.0 0.0 0.0" range="-30 30" type="hinge" />
                  <geom fromto="0.0 0.0 0.0 0.0 -0.2828427 0.0" name="front_4_leg_geom" size="0.046"
                    type="capsule" />
                  <body pos="0.0 -0.2828427 0">
                    <joint axis="1 1 0" name="ankle_11" pos="0.0 0.0 0.0" range="30 70" type="hinge" />
                    <geom fromto="0.0 0.0 0.0 0.0 -0.56568542 0.0" name="front_11_ankle_geom"
                      size="0.046"
                      type="capsule" />
                  </body>
                </body>
              </body>
              <body name="back_5_leg" pos=".5 0 0">
                <geom fromto="0.0 0.0 0.0 0.0 0.2828427 0.0" name="aux_12_geom" size="0.046"
                  type="capsule" />
                <body name="aux_12" pos="0.0 0.2828427 0">
                  <joint axis="0 0 1" name="hip_12" pos="0.0 0.0 0.0" range="-30 30" type="hinge" />
                  <geom fromto="0.0 0.0 0.0 0.0 0.2828427 0.0" name="back_5_leg_geom" size="0.046"
                    type="capsule" />
                  <body pos="0.0 0.2828427 0">
                    <joint axis="1 1 0" name="ankle_12" pos="0.0 0.0 0.0" range="-70 -30"
                      type="hinge" />
                    <geom fromto="0.0 0.0 0.0 0.0 0.56568542 0.0" name="back_12_ankle_geom"
                      size="0.046"
                      type="capsule" />
                  </body>
                </body>
              </body>
              <body name="seg5" pos=".5 0 0">
                <joint axis="0 0 1" name="seg_5" pos="0.0 0.0 0.0" range="-30 30" type="hinge" />
                <geom fromto="0.0 0.0 0.0 0.5 0.0 0.0" name="seg_5_geom" size="0.09" type="capsule" />
                <body name="front_6_leg" pos=".5 0 0">
                  <geom fromto="0.0 0.0 0.0 0.0 -0.2828427 0.0" name="aux_13_geom" size="0.046"
                    type="capsule" />
                  <body name="aux_13" pos="0.0 -0.2828427 0">
                    <joint axis="0 0 1" name="hip_13" pos="0.0 0.0 0.0" range="-30 30" type="hinge" />
                    <geom fromto="0.0 0.0 0.0 0.0 -0.2828427 0.0" name="front_6_leg_geom"
                      size="0.046"
                      type="capsule" />
                    <body pos="0.0 -0.2828427 0">
                      <joint axis="1 1 0" name="ankle_13" pos="0.0 0.0 0.0" range="30 70"
                        type="hinge" />
                      <geom fromto="0.0 0.0 0.0 0.0 -0.56568542 0.0" name="front_13_ankle_geom"
                        size="0.046"
                        type="capsule" />
                    </body>
                  </body>
                </body>
                <body name="back_6_leg" pos=".5 0 0">
                  <geom fromto="0.0 0.0 0.0 0.0 0.2828427 0.0" name="aux_14_geom" size="0.046"
                    type="capsule" />
                  <body name="aux_14" pos="0.0 0.2828427 0">
                    <joint axis="0 0 1" name="hip_14" pos="0.0 0.0 0.0" range="-30 30" type="hinge" />
                    <geom fromto="0.0 0.0 0.0 0.0 0.2828427 0.0" name="back_6_leg_geom" size="0.046"
                      type="capsule" />
                    <body pos="0.0 0.2828427 0">
                      <joint axis="1 1 0" name="ankle_14" pos="0.0 0.0 0.0" range="-70 -30"
                        type="hinge" />
                      <geom fromto="0.0 0.0 0.0 0.0 0.56568542 0.0" name="back_14_ankle_geom"
                        size="0.046"
                        type="capsule" />
                    </body>
                  </body>
                </body>
                <body name="seg6" pos=".5 0 0">
                  <joint axis="0 0 1" name="seg_6" pos="0.0 0.0 0.0" range="-30 30" type="hinge" />
                  <geom fromto="0.0 0.0 0.0 0.5 0.0 0.0" name="seg_6_geom" size="0.09"
                    type="capsule" />
                  <body name="front_7_leg" pos=".5 0 0">
                    <geom fromto="0.0 0.0 0.0 0.0 -0.2828427 0.0" name="aux_15_geom" size="0.046"
                      type="capsule" />
                    <body name="aux_15" pos="0.0 -0.2828427 0">
                      <joint axis="0 0 1" name="hip_15" pos="0.0 0.0 0.0" range="-30 30"
                        type="hinge" />
                      <geom fromto="0.0 0.0 0.0 0.0 -0.2828427 0.0" name="front_7_leg_geom"
                        size="0.046"
                        type="capsule" />
                      <body pos="0.0 -0.2828427 0">
                        <joint axis="1 1 0" name="ankle_15" pos="0.0 0.0 0.0" range="30 70"
                          type="hinge" />
                        <geom fromto="0.0 0.0 0.0 0.0 -0.56568542 0.0" name="front_15_ankle_geom"
                          size="0.046"
                          type="capsule" />
                      </body>
                    </body>
                  </body>
                  <body name="back_7_leg" pos=".5 0 0">
                    <geom fromto="0.0 0.0 0.0 0.0 0.2828427 0.0" name="aux_16_geom" size="0.046"
                      type="capsule" />
                    <body name="aux_16" pos="0.0 0.2828427 0">
                      <joint axis="0 0 1" name="hip_16" pos="0.0 0.0 0.0" range="-30 30"
                        type="hinge" />
                      <geom fromto="0.0 0.0 0.0 0.0 0.2828427 0.0" name="back_7_leg_geom"
                        size="0.046"
                        type="capsule" />
                      <body pos="0.0 0.2828427 0">
                        <joint axis="1 1 0" name="ankle_16" pos="0.0 0.0 0.0" range="-70 -30"
                          type="hinge" />
                        <geom fromto="0.0 0.0 0.0 0.0 0.56568542 0.0" name="back_16_ankle_geom"
                          size="0.046"
                          type="capsule" />
                      </body>
                    </body>
                  </body>
                  <body name="seg7" pos=".5 0 0">
                    <joint axis="0 0 1" name="seg_7" pos="0.0 0.0 0.0" range="-30 30" type="hinge" />
                    <geom fromto="0.0 0.0 0.0 0.5 0.0 0.0" name="seg_7_geom" size="0.09"
                      type="capsule" />
                    <body name="right_back_leg" pos="0.5 0 0">
                      <geom fromto="0.0 0.0 0.0 0.2 -0.2 0.0" name="aux_17_geom" size="0.046"
                        type="capsule" />
                      <body name="aux_17" pos="0.2 -0.2 0">
                        <joint axis="0 0 1" name="hip_17" pos="0.0 0.0 0.0" range="-30 30"
                          type="hinge" />
                        <geom fromto="0.0 0.0 0.0 0.2 -0.2 0.0" name="rightback_leg_geom"
                          size="0.046" type="capsule" />
                        <body pos="0.2 -0.2 0">
                          <joint axis="1 1 0" name="ankle_17" pos="0.0 0.0 0.0" range="30 70"
                            type="hinge" />
                          <geom fromto="0.0 0.0 0.0 0.4 -0.4 0.0" name="backend_ankle_geom"
                            size="0.046" type="capsule" />
                        </body>
                      </body>
                    </body>
                    <body name="front_end_leg" pos=".5 0 0">
                      <geom fromto="0.0 0.0 0.0 0.2 0.2 0.0" name="aux_18_geom" size="0.046"
                        type="capsule" />
                      <body name="aux_18" pos="0.2 0.2 0">
                        <joint axis="0 0 1" name="hip_18" pos="0.0 0.0 0.0" range="-30 30"
                          type="hinge" />
                        <geom fromto="0.0 0.0 0.0 0.2 0.2 0.0" name="front_end_leg_geom" size="0.046"
                          type="capsule" />
                        <body pos="0.2 0.2 0">
                          <joint axis="-1 1 0" name="ankle_18" pos="0.0 0.0 0.0" range="30 70"
                            type="hinge" />
                          <geom fromto="0.0 0.0 0.0 0.4 0.4 0.0" name="frontend_ankle_geom"
                            size="0.046" type="capsule" />
                        </body>
                      </body>
                    </body>


                  </body>

                </body>

              </body>

            </body>

          </body>


        </body>

      </body>


    </body>
  </worldbody>
  <actuator>
    <motor ctrllimited="true" ctrlrange="-1.0 1.0" joint="hip_1" gear="150" />
    <motor ctrllimited="true" ctrlrange="-1.0 1.0" joint="ankle_1" gear="150" />
    <motor ctrllimited="true" ctrlrange="-1.0 1.0" joint="hip_2" gear="150" />
    <motor ctrllimited="true" ctrlrange="-1.0 1.0" joint="ankle_2" gear="150" />
    <motor ctrllimited="true" ctrlrange="-1.0 1.0" joint="hip_3" gear="150" />
    <motor ctrllimited="true" ctrlrange="-1.0 1.0" joint="ankle_3" gear="150" />
    <motor ctrllimited="true" ctrlrange="-1.0 1.0" joint="hip_4" gear="150" />
    <motor ctrllimited="true" ctrlrange="-1.0 1.0" joint="ankle_4" gear="150" />
    <motor ctrllimited="true" ctrlrange="-1.0 1.0" joint="hip_5" gear="150" />
    <motor ctrllimited="true" ctrlrange="-1.0 1.0" joint="ankle_5" gear="150" />
    <motor ctrllimited="true" ctrlrange="-1.0 1.0" joint="hip_6" gear="150" />
    <motor ctrllimited="true" ctrlrange="-1.0 1.0" joint="ankle_6" gear="150" />
    <motor ctrllimited="true" ctrlrange="-1.0 1.0" joint="hip_7" gear="150" />
    <motor ctrllimited="true" ctrlrange="-1.0 1.0" joint="ankle_7" gear="150" />
    <motor ctrllimited="true" ctrlrange="-1.0 1.0" joint="hip_8" gear="150" />
    <motor ctrllimited="true" ctrlrange="-1.0 1.0" joint="ankle_8" gear="150" />
    <motor ctrllimited="true" ctrlrange="-1.0 1.0" joint="hip_9" gear="150" />
    <motor ctrllimited="true" ctrlrange="-1.0 1.0" joint="ankle_9" gear="150" />
    <motor ctrllimited="true" ctrlrange="-1.0 1.0" joint="hip_10" gear="150" />
    <motor ctrllimited="true" ctrlrange="-1.0 1.0" joint="ankle_10" gear="150" />
    <motor ctrllimited="true" ctrlrange="-1.0 1.0" joint="hip_11" gear="150" />
    <motor ctrllimited="true" ctrlrange="-1.0 1.0" joint="ankle_11" gear="150" />
    <motor ctrllimited="true" ctrlrange="-1.0 1.0" joint="hip_12" gear="150" />
    <motor ctrllimited="true" ctrlrange="-1.0 1.0" joint="ankle_12" gear="150" />
    <motor ctrllimited="true" ctrlrange="-1.0 1.0" joint="hip_13" gear="150" />
    <motor ctrllimited="true" ctrlrange="-1.0 1.0" joint="ankle_13" gear="150" />
    <motor ctrllimited="true" ctrlrange="-1.0 1.0" joint="hip_14" gear="150" />
    <motor ctrllimited="true" ctrlrange="-1.0 1.0" joint="ankle_14" gear="150" />
    <motor ctrllimited="true" ctrlrange="-1.0 1.0" joint="hip_15" gear="150" />
    <motor ctrllimited="true" ctrlrange="-1.0 1.0" joint="ankle_15" gear="150" />
    <motor ctrllimited="true" ctrlrange="-1.0 1.0" joint="hip_16" gear="150" />
    <motor ctrllimited="true" ctrlrange="-1.0 1.0" joint="ankle_16" gear="150" />
    <motor ctrllimited="true" ctrlrange="-1.0 1.0" joint="hip_17" gear="150" />
    <motor ctrllimited="true" ctrlrange="-1.0 1.0" joint="ankle_17" gear="150" />
    <motor ctrllimited="true" ctrlrange="-1.0 1.0" joint="hip_18" gear="150" />
    <motor ctrllimited="true" ctrlrange="-1.0 1.0" joint="ankle_18" gear="150" />
  </actuator>
</mujoco>